2022-06-07 21:05:09,789--test_login.py--44--INFO:用例【登录成功】---执行成功
2022-06-07 21:05:09,818--test_login.py--44--INFO:用例【账号为空】---执行成功
2022-06-07 21:05:09,848--test_login.py--44--INFO:用例【密码为空】---执行成功
2022-06-07 21:05:09,879--test_login.py--44--INFO:用例【密码错误】---执行成功
2022-06-07 21:05:09,911--test_login.py--38--ERROR:用例【密码错误2】---执行失败
2022-06-07 21:05:09,911--test_login.py--40--ERROR:{'code': 1, 'msg': '账号不正确'} != {'code': 1, 'msg': '账号或密码不正确'}
- {'code': 1, 'msg': '账号不正确'}
+ {'code': 1, 'msg': '账号或密码不正确'}
?                       +++
Traceback (most recent call last):
  File "D:\pythonworkspace\python01\project02\testcases\test_login.py", line 35, in test_login
    self.assertEqual(expected, res)
  File "C:\Users\Administrator\AppData\Local\Programs\Python\Python37\lib\unittest\case.py", line 839, in assertEqual
    assertion_func(first, second, msg=msg)
  File "C:\Users\Administrator\AppData\Local\Programs\Python\Python37\lib\unittest\case.py", line 1138, in assertDictEqual
    self.fail(self._formatMessage(msg, standardMsg))
  File "C:\Users\Administrator\AppData\Local\Programs\Python\Python37\lib\unittest\case.py", line 680, in fail
    raise self.failureException(msg)
AssertionError: {'code': 1, 'msg': '账号不正确'} != {'code': 1, 'msg': '账号或密码不正确'}
- {'code': 1, 'msg': '账号不正确'}
+ {'code': 1, 'msg': '账号或密码不正确'}
?                       +++

2022-06-09 22:28:50,051--test_login.py--44--INFO:用例【登录成功】---执行成功
2022-06-09 22:28:50,094--test_login.py--44--INFO:用例【账号为空】---执行成功
2022-06-09 22:28:50,131--test_login.py--44--INFO:用例【密码为空】---执行成功
2022-06-09 22:28:50,169--test_login.py--44--INFO:用例【密码错误】---执行成功
2022-06-09 22:28:50,211--test_login.py--38--ERROR:用例【密码错误2】---执行失败
2022-06-09 22:28:50,211--test_login.py--40--ERROR:{'code': 1, 'msg': '账号不正确'} != {'code': 1, 'msg': '账号或密码不正确'}
- {'code': 1, 'msg': '账号不正确'}
+ {'code': 1, 'msg': '账号或密码不正确'}
?                       +++
Traceback (most recent call last):
  File "D:\pythonworkspace\python01\project02\testcases\test_login.py", line 35, in test_login
    self.assertEqual(expected, res)
  File "C:\Users\Administrator\AppData\Local\Programs\Python\Python37\lib\unittest\case.py", line 839, in assertEqual
    assertion_func(first, second, msg=msg)
  File "C:\Users\Administrator\AppData\Local\Programs\Python\Python37\lib\unittest\case.py", line 1138, in assertDictEqual
    self.fail(self._formatMessage(msg, standardMsg))
  File "C:\Users\Administrator\AppData\Local\Programs\Python\Python37\lib\unittest\case.py", line 680, in fail
    raise self.failureException(msg)
AssertionError: {'code': 1, 'msg': '账号不正确'} != {'code': 1, 'msg': '账号或密码不正确'}
- {'code': 1, 'msg': '账号不正确'}
+ {'code': 1, 'msg': '账号或密码不正确'}
?                       +++

