2022-06-05 23:48:38,792--test_login.py--43--INFO:用例【登录成功】---执行成功
2022-06-05 23:48:38,822--test_login.py--43--INFO:用例【账号为空】---执行成功
2022-06-05 23:48:38,852--test_login.py--43--INFO:用例【密码为空】---执行成功
2022-06-05 23:48:38,883--test_login.py--43--INFO:用例【密码错误】---执行成功
2022-06-05 23:48:38,914--test_login.py--37--ERROR:用例【密码错误2】---执行失败
2022-06-05 23:48:38,914--test_login.py--39--ERROR:{'code': 1, 'msg': '账号不正确'} != {'code': 1, 'msg': '账号或密码不正确'}
- {'code': 1, 'msg': '账号不正确'}
+ {'code': 1, 'msg': '账号或密码不正确'}
?                       +++
Traceback (most recent call last):
  File "D:\pythonworkspace\project01\testcases\test_login.py", line 34, in test_login
    self.assertEqual(expected, res)
  File "C:\Users\Administrator\AppData\Local\Programs\Python\Python37\lib\unittest\case.py", line 839, in assertEqual
    assertion_func(first, second, msg=msg)
  File "C:\Users\Administrator\AppData\Local\Programs\Python\Python37\lib\unittest\case.py", line 1138, in assertDictEqual
    self.fail(self._formatMessage(msg, standardMsg))
  File "C:\Users\Administrator\AppData\Local\Programs\Python\Python37\lib\unittest\case.py", line 680, in fail
    raise self.failureException(msg)
AssertionError: {'code': 1, 'msg': '账号不正确'} != {'code': 1, 'msg': '账号或密码不正确'}
- {'code': 1, 'msg': '账号不正确'}
+ {'code': 1, 'msg': '账号或密码不正确'}
?                       +++

2022-06-07 20:09:26,652--test_login.py--43--INFO:用例【登录成功】---执行成功
2022-06-07 20:09:26,703--test_login.py--43--INFO:用例【账号为空】---执行成功
2022-06-07 20:09:26,755--test_login.py--43--INFO:用例【密码为空】---执行成功
2022-06-07 20:09:26,804--test_login.py--43--INFO:用例【密码错误】---执行成功
2022-06-07 20:09:26,911--test_login.py--37--ERROR:用例【密码错误2】---执行失败
2022-06-07 20:09:26,911--test_login.py--39--ERROR:{'code': 1, 'msg': '账号不正确'} != {'code': 1, 'msg': '账号或密码不正确'}
- {'code': 1, 'msg': '账号不正确'}
+ {'code': 1, 'msg': '账号或密码不正确'}
?                       +++
Traceback (most recent call last):
  File "D:\pythonworkspace\project01\testcases\test_login.py", line 34, in test_login
    self.assertEqual(expected, res)
  File "C:\Users\Administrator\AppData\Local\Programs\Python\Python37\lib\unittest\case.py", line 839, in assertEqual
    assertion_func(first, second, msg=msg)
  File "C:\Users\Administrator\AppData\Local\Programs\Python\Python37\lib\unittest\case.py", line 1138, in assertDictEqual
    self.fail(self._formatMessage(msg, standardMsg))
  File "C:\Users\Administrator\AppData\Local\Programs\Python\Python37\lib\unittest\case.py", line 680, in fail
    raise self.failureException(msg)
AssertionError: {'code': 1, 'msg': '账号不正确'} != {'code': 1, 'msg': '账号或密码不正确'}
- {'code': 1, 'msg': '账号不正确'}
+ {'code': 1, 'msg': '账号或密码不正确'}
?                       +++

2022-06-07 20:09:48,287--test_login.py--43--INFO:用例【登录成功】---执行成功
2022-06-07 20:09:48,323--test_login.py--43--INFO:用例【账号为空】---执行成功
2022-06-07 20:09:48,360--test_login.py--43--INFO:用例【密码为空】---执行成功
2022-06-07 20:09:48,396--test_login.py--43--INFO:用例【密码错误】---执行成功
2022-06-07 20:09:48,433--test_login.py--37--ERROR:用例【密码错误2】---执行失败
2022-06-07 20:09:48,433--test_login.py--39--ERROR:{'code': 1, 'msg': '账号不正确'} != {'code': 1, 'msg': '账号或密码不正确'}
- {'code': 1, 'msg': '账号不正确'}
+ {'code': 1, 'msg': '账号或密码不正确'}
?                       +++
Traceback (most recent call last):
  File "D:\pythonworkspace\project01\testcases\test_login.py", line 34, in test_login
    self.assertEqual(expected, res)
  File "C:\Users\Administrator\AppData\Local\Programs\Python\Python37\lib\unittest\case.py", line 839, in assertEqual
    assertion_func(first, second, msg=msg)
  File "C:\Users\Administrator\AppData\Local\Programs\Python\Python37\lib\unittest\case.py", line 1138, in assertDictEqual
    self.fail(self._formatMessage(msg, standardMsg))
  File "C:\Users\Administrator\AppData\Local\Programs\Python\Python37\lib\unittest\case.py", line 680, in fail
    raise self.failureException(msg)
AssertionError: {'code': 1, 'msg': '账号不正确'} != {'code': 1, 'msg': '账号或密码不正确'}
- {'code': 1, 'msg': '账号不正确'}
+ {'code': 1, 'msg': '账号或密码不正确'}
?                       +++

2022-06-07 20:19:07,422--test_login.py--43--INFO:用例【登录成功】---执行成功
2022-06-07 20:19:07,459--test_login.py--43--INFO:用例【账号为空】---执行成功
2022-06-07 20:19:07,496--test_login.py--43--INFO:用例【密码为空】---执行成功
2022-06-07 20:19:07,533--test_login.py--43--INFO:用例【密码错误】---执行成功
2022-06-07 20:19:07,571--test_login.py--37--ERROR:用例【密码错误2】---执行失败
2022-06-07 20:19:07,571--test_login.py--39--ERROR:{'code': 1, 'msg': '账号不正确'} != {'code': 1, 'msg': '账号或密码不正确'}
- {'code': 1, 'msg': '账号不正确'}
+ {'code': 1, 'msg': '账号或密码不正确'}
?                       +++
Traceback (most recent call last):
  File "D:\pythonworkspace\python01\project01\testcases\test_login.py", line 34, in test_login
    self.assertEqual(expected, res)
  File "C:\Users\Administrator\AppData\Local\Programs\Python\Python37\lib\unittest\case.py", line 839, in assertEqual
    assertion_func(first, second, msg=msg)
  File "C:\Users\Administrator\AppData\Local\Programs\Python\Python37\lib\unittest\case.py", line 1138, in assertDictEqual
    self.fail(self._formatMessage(msg, standardMsg))
  File "C:\Users\Administrator\AppData\Local\Programs\Python\Python37\lib\unittest\case.py", line 680, in fail
    raise self.failureException(msg)
AssertionError: {'code': 1, 'msg': '账号不正确'} != {'code': 1, 'msg': '账号或密码不正确'}
- {'code': 1, 'msg': '账号不正确'}
+ {'code': 1, 'msg': '账号或密码不正确'}
?                       +++

